[2023-12-01T17:56:11.709+0000] {taskinstance.py:1159} INFO - Dependencies all met for dep_context=non-requeueable deps ti=<TaskInstance: heart_attack_classification.test_model manual__2023-12-01T17:55:00.781189+00:00 [queued]>
[2023-12-01T17:56:11.714+0000] {taskinstance.py:1159} INFO - Dependencies all met for dep_context=requeueable deps ti=<TaskInstance: heart_attack_classification.test_model manual__2023-12-01T17:55:00.781189+00:00 [queued]>
[2023-12-01T17:56:11.715+0000] {taskinstance.py:1361} INFO - Starting attempt 2 of 3
[2023-12-01T17:56:11.725+0000] {taskinstance.py:1382} INFO - Executing <Task(PythonOperator): test_model> on 2023-12-01 17:55:00.781189+00:00
[2023-12-01T17:56:11.732+0000] {standard_task_runner.py:57} INFO - Started process 195 to run task
[2023-12-01T17:56:11.734+0000] {standard_task_runner.py:84} INFO - Running: ['***', 'tasks', 'run', 'heart_attack_classification', 'test_model', 'manual__2023-12-01T17:55:00.781189+00:00', '--job-id', '68', '--raw', '--subdir', 'DAGS_FOLDER/ml_pipeline.py', '--cfg-path', '/tmp/tmpz810e3b8']
[2023-12-01T17:56:11.735+0000] {standard_task_runner.py:85} INFO - Job 68: Subtask test_model
[2023-12-01T17:56:11.766+0000] {task_command.py:416} INFO - Running <TaskInstance: heart_attack_classification.test_model manual__2023-12-01T17:55:00.781189+00:00 [running]> on host 006789861f2e
[2023-12-01T17:56:11.815+0000] {taskinstance.py:1662} INFO - Exporting env vars: AIRFLOW_CTX_DAG_OWNER='jino' AIRFLOW_CTX_DAG_ID='heart_attack_classification' AIRFLOW_CTX_TASK_ID='test_model' AIRFLOW_CTX_EXECUTION_DATE='2023-12-01T17:55:00.781189+00:00' AIRFLOW_CTX_TRY_NUMBER='2' AIRFLOW_CTX_DAG_RUN_ID='manual__2023-12-01T17:55:00.781189+00:00'
[2023-12-01T17:56:11.823+0000] {logging_mixin.py:154} INFO - None
[2023-12-01T17:56:11.824+0000] {taskinstance.py:1937} ERROR - Task failed with exception
Traceback (most recent call last):
  File "/home/airflow/.local/lib/python3.8/site-packages/airflow/operators/python.py", line 192, in execute
    return_value = self.execute_callable()
  File "/home/airflow/.local/lib/python3.8/site-packages/airflow/operators/python.py", line 209, in execute_callable
    return self.python_callable(*self.op_args, **self.op_kwargs)
  File "/opt/airflow/dags/ml_pipeline.py", line 66, in test_model
    model = joblib.load(model_filepath)
  File "/home/airflow/.local/lib/python3.8/site-packages/joblib/numpy_pickle.py", line 650, in load
    with open(filename, 'rb') as f:
TypeError: expected str, bytes or os.PathLike object, not NoneType
[2023-12-01T17:56:11.831+0000] {taskinstance.py:1400} INFO - Marking task as UP_FOR_RETRY. dag_id=heart_attack_classification, task_id=test_model, execution_date=20231201T175500, start_date=20231201T175611, end_date=20231201T175611
[2023-12-01T17:56:11.839+0000] {standard_task_runner.py:104} ERROR - Failed to execute job 68 for task test_model (expected str, bytes or os.PathLike object, not NoneType; 195)
[2023-12-01T17:56:11.867+0000] {local_task_job_runner.py:228} INFO - Task exited with return code 1
[2023-12-01T17:56:11.880+0000] {taskinstance.py:2778} INFO - 0 downstream tasks scheduled from follow-on schedule check
