[2023-12-01T17:48:35.476+0000] {taskinstance.py:1159} INFO - Dependencies all met for dep_context=non-requeueable deps ti=<TaskInstance: heart_attack_classification.test_model manual__2023-12-01T17:48:27.673426+00:00 [queued]>
[2023-12-01T17:48:35.482+0000] {taskinstance.py:1159} INFO - Dependencies all met for dep_context=requeueable deps ti=<TaskInstance: heart_attack_classification.test_model manual__2023-12-01T17:48:27.673426+00:00 [queued]>
[2023-12-01T17:48:35.482+0000] {taskinstance.py:1361} INFO - Starting attempt 1 of 3
[2023-12-01T17:48:35.491+0000] {taskinstance.py:1382} INFO - Executing <Task(PythonOperator): test_model> on 2023-12-01 17:48:27.673426+00:00
[2023-12-01T17:48:35.497+0000] {standard_task_runner.py:57} INFO - Started process 189 to run task
[2023-12-01T17:48:35.498+0000] {standard_task_runner.py:84} INFO - Running: ['***', 'tasks', 'run', 'heart_attack_classification', 'test_model', 'manual__2023-12-01T17:48:27.673426+00:00', '--job-id', '58', '--raw', '--subdir', 'DAGS_FOLDER/ml_pipeline.py', '--cfg-path', '/tmp/tmpm9xz49zz']
[2023-12-01T17:48:35.499+0000] {standard_task_runner.py:85} INFO - Job 58: Subtask test_model
[2023-12-01T17:48:35.527+0000] {task_command.py:416} INFO - Running <TaskInstance: heart_attack_classification.test_model manual__2023-12-01T17:48:27.673426+00:00 [running]> on host 044b6cac997a
[2023-12-01T17:48:35.571+0000] {taskinstance.py:1662} INFO - Exporting env vars: AIRFLOW_CTX_DAG_OWNER='jino' AIRFLOW_CTX_DAG_ID='heart_attack_classification' AIRFLOW_CTX_TASK_ID='test_model' AIRFLOW_CTX_EXECUTION_DATE='2023-12-01T17:48:27.673426+00:00' AIRFLOW_CTX_TRY_NUMBER='1' AIRFLOW_CTX_DAG_RUN_ID='manual__2023-12-01T17:48:27.673426+00:00'
[2023-12-01T17:48:35.579+0000] {taskinstance.py:1937} ERROR - Task failed with exception
Traceback (most recent call last):
  File "/home/airflow/.local/lib/python3.8/site-packages/airflow/operators/python.py", line 192, in execute
    return_value = self.execute_callable()
  File "/home/airflow/.local/lib/python3.8/site-packages/airflow/operators/python.py", line 209, in execute_callable
    return self.python_callable(*self.op_args, **self.op_kwargs)
  File "/opt/airflow/dags/ml_pipeline.py", line 65, in test_model
    model = joblib.load(model_filepath)
  File "/home/airflow/.local/lib/python3.8/site-packages/joblib/numpy_pickle.py", line 650, in load
    with open(filename, 'rb') as f:
TypeError: expected str, bytes or os.PathLike object, not NoneType
[2023-12-01T17:48:35.586+0000] {taskinstance.py:1400} INFO - Marking task as UP_FOR_RETRY. dag_id=heart_attack_classification, task_id=test_model, execution_date=20231201T174827, start_date=20231201T174835, end_date=20231201T174835
[2023-12-01T17:48:35.594+0000] {standard_task_runner.py:104} ERROR - Failed to execute job 58 for task test_model (expected str, bytes or os.PathLike object, not NoneType; 189)
[2023-12-01T17:48:35.631+0000] {local_task_job_runner.py:228} INFO - Task exited with return code 1
[2023-12-01T17:48:35.643+0000] {taskinstance.py:2778} INFO - 0 downstream tasks scheduled from follow-on schedule check
