[2023-12-01T17:49:36.890+0000] {taskinstance.py:1159} INFO - Dependencies all met for dep_context=non-requeueable deps ti=<TaskInstance: heart_attack_classification.test_model manual__2023-12-01T17:48:27.673426+00:00 [queued]>
[2023-12-01T17:49:36.896+0000] {taskinstance.py:1159} INFO - Dependencies all met for dep_context=requeueable deps ti=<TaskInstance: heart_attack_classification.test_model manual__2023-12-01T17:48:27.673426+00:00 [queued]>
[2023-12-01T17:49:36.896+0000] {taskinstance.py:1361} INFO - Starting attempt 2 of 3
[2023-12-01T17:49:36.906+0000] {taskinstance.py:1382} INFO - Executing <Task(PythonOperator): test_model> on 2023-12-01 17:48:27.673426+00:00
[2023-12-01T17:49:36.912+0000] {standard_task_runner.py:57} INFO - Started process 259 to run task
[2023-12-01T17:49:36.914+0000] {standard_task_runner.py:84} INFO - Running: ['***', 'tasks', 'run', 'heart_attack_classification', 'test_model', 'manual__2023-12-01T17:48:27.673426+00:00', '--job-id', '60', '--raw', '--subdir', 'DAGS_FOLDER/ml_pipeline.py', '--cfg-path', '/tmp/tmp5uo4f5u_']
[2023-12-01T17:49:36.915+0000] {standard_task_runner.py:85} INFO - Job 60: Subtask test_model
[2023-12-01T17:49:36.942+0000] {task_command.py:416} INFO - Running <TaskInstance: heart_attack_classification.test_model manual__2023-12-01T17:48:27.673426+00:00 [running]> on host 044b6cac997a
[2023-12-01T17:49:36.984+0000] {taskinstance.py:1662} INFO - Exporting env vars: AIRFLOW_CTX_DAG_OWNER='jino' AIRFLOW_CTX_DAG_ID='heart_attack_classification' AIRFLOW_CTX_TASK_ID='test_model' AIRFLOW_CTX_EXECUTION_DATE='2023-12-01T17:48:27.673426+00:00' AIRFLOW_CTX_TRY_NUMBER='2' AIRFLOW_CTX_DAG_RUN_ID='manual__2023-12-01T17:48:27.673426+00:00'
[2023-12-01T17:49:36.990+0000] {taskinstance.py:1937} ERROR - Task failed with exception
Traceback (most recent call last):
  File "/home/airflow/.local/lib/python3.8/site-packages/airflow/operators/python.py", line 192, in execute
    return_value = self.execute_callable()
  File "/home/airflow/.local/lib/python3.8/site-packages/airflow/operators/python.py", line 209, in execute_callable
    return self.python_callable(*self.op_args, **self.op_kwargs)
  File "/opt/airflow/dags/ml_pipeline.py", line 65, in test_model
    model = joblib.load(model_filepath)
  File "/home/airflow/.local/lib/python3.8/site-packages/joblib/numpy_pickle.py", line 650, in load
    with open(filename, 'rb') as f:
TypeError: expected str, bytes or os.PathLike object, not NoneType
[2023-12-01T17:49:36.997+0000] {taskinstance.py:1400} INFO - Marking task as UP_FOR_RETRY. dag_id=heart_attack_classification, task_id=test_model, execution_date=20231201T174827, start_date=20231201T174936, end_date=20231201T174936
[2023-12-01T17:49:37.004+0000] {standard_task_runner.py:104} ERROR - Failed to execute job 60 for task test_model (expected str, bytes or os.PathLike object, not NoneType; 259)
[2023-12-01T17:49:37.047+0000] {local_task_job_runner.py:228} INFO - Task exited with return code 1
[2023-12-01T17:49:37.059+0000] {taskinstance.py:2778} INFO - 0 downstream tasks scheduled from follow-on schedule check
