[2023-12-01T17:46:06.219+0000] {taskinstance.py:1159} INFO - Dependencies all met for dep_context=non-requeueable deps ti=<TaskInstance: heart_attack_classification.preprocess_data manual__2023-12-01T17:46:02.587665+00:00 [queued]>
[2023-12-01T17:46:06.224+0000] {taskinstance.py:1159} INFO - Dependencies all met for dep_context=requeueable deps ti=<TaskInstance: heart_attack_classification.preprocess_data manual__2023-12-01T17:46:02.587665+00:00 [queued]>
[2023-12-01T17:46:06.225+0000] {taskinstance.py:1361} INFO - Starting attempt 1 of 3
[2023-12-01T17:46:06.233+0000] {taskinstance.py:1382} INFO - Executing <Task(PythonOperator): preprocess_data> on 2023-12-01 17:46:02.587665+00:00
[2023-12-01T17:46:06.238+0000] {standard_task_runner.py:57} INFO - Started process 102 to run task
[2023-12-01T17:46:06.240+0000] {standard_task_runner.py:84} INFO - Running: ['***', 'tasks', 'run', 'heart_attack_classification', 'preprocess_data', 'manual__2023-12-01T17:46:02.587665+00:00', '--job-id', '51', '--raw', '--subdir', 'DAGS_FOLDER/ml_pipeline.py', '--cfg-path', '/tmp/tmpbwcv1pgh']
[2023-12-01T17:46:06.240+0000] {standard_task_runner.py:85} INFO - Job 51: Subtask preprocess_data
[2023-12-01T17:46:06.267+0000] {task_command.py:416} INFO - Running <TaskInstance: heart_attack_classification.preprocess_data manual__2023-12-01T17:46:02.587665+00:00 [running]> on host 1eb2030ec5e2
[2023-12-01T17:46:06.309+0000] {taskinstance.py:1662} INFO - Exporting env vars: AIRFLOW_CTX_DAG_OWNER='jino' AIRFLOW_CTX_DAG_ID='heart_attack_classification' AIRFLOW_CTX_TASK_ID='preprocess_data' AIRFLOW_CTX_EXECUTION_DATE='2023-12-01T17:46:02.587665+00:00' AIRFLOW_CTX_TRY_NUMBER='1' AIRFLOW_CTX_DAG_RUN_ID='manual__2023-12-01T17:46:02.587665+00:00'
[2023-12-01T17:46:06.350+0000] {taskinstance.py:1937} ERROR - Task failed with exception
Traceback (most recent call last):
  File "/home/airflow/.local/lib/python3.8/site-packages/pandas/core/indexes/base.py", line 3653, in get_loc
    return self._engine.get_loc(casted_key)
  File "pandas/_libs/index.pyx", line 147, in pandas._libs.index.IndexEngine.get_loc
  File "pandas/_libs/index.pyx", line 176, in pandas._libs.index.IndexEngine.get_loc
  File "pandas/_libs/hashtable_class_helper.pxi", line 7080, in pandas._libs.hashtable.PyObjectHashTable.get_item
  File "pandas/_libs/hashtable_class_helper.pxi", line 7088, in pandas._libs.hashtable.PyObjectHashTable.get_item
KeyError: 'Sex'

The above exception was the direct cause of the following exception:

Traceback (most recent call last):
  File "/home/airflow/.local/lib/python3.8/site-packages/airflow/operators/python.py", line 192, in execute
    return_value = self.execute_callable()
  File "/home/airflow/.local/lib/python3.8/site-packages/airflow/operators/python.py", line 209, in execute_callable
    return self.python_callable(*self.op_args, **self.op_kwargs)
  File "/opt/airflow/dags/ml_pipeline.py", line 28, in preprocess_data
    df['Sex'] = le.fit_transform(df['Sex'])
  File "/home/airflow/.local/lib/python3.8/site-packages/pandas/core/frame.py", line 3761, in __getitem__
    indexer = self.columns.get_loc(key)
  File "/home/airflow/.local/lib/python3.8/site-packages/pandas/core/indexes/base.py", line 3655, in get_loc
    raise KeyError(key) from err
KeyError: 'Sex'
[2023-12-01T17:46:06.360+0000] {taskinstance.py:1400} INFO - Marking task as UP_FOR_RETRY. dag_id=heart_attack_classification, task_id=preprocess_data, execution_date=20231201T174602, start_date=20231201T174606, end_date=20231201T174606
[2023-12-01T17:46:06.369+0000] {standard_task_runner.py:104} ERROR - Failed to execute job 51 for task preprocess_data ('Sex'; 102)
[2023-12-01T17:46:06.412+0000] {local_task_job_runner.py:228} INFO - Task exited with return code 1
[2023-12-01T17:46:06.429+0000] {taskinstance.py:2778} INFO - 0 downstream tasks scheduled from follow-on schedule check
